<?xml version="1.0"?>
<robot xmlns:xacro="http://www.ros.org/wiki/xacro" name="robot">
    <xacro:include filename="inertial_macros.xacro" />
    <material name="white">
        <color rgba="1 1 1 1" />
    </material>
    <material name="black">
        <color rgba="0 0 0 1" />
    </material>
    <material name="red">
        <color rgba="1 0 0 1" />
    </material>
    <material name="green">
        <color rgba="0 1 0 1" />
    </material>
    <material name="blue">
        <color rgba="0 0 1 1" />
    </material>
    <material name="yellow">
        <color rgba="1 1 0 1" />
    </material>
    <material name="orange">
        <color rgba="1 0.5 0 1" />
    </material>
    <material name="purple">
        <color rgba="0.5 0 1 1" />
    </material>
    <material name="pink">
        <color rgba="1 0 1 1" />
    </material>
    <material name="cyan">
        <color rgba="0 1 1 1" />
    </material>
    <material name="grey">
        <color rgba="0.5 0.5 0.5 1" />
    </material>
    <material name="light_grey">
        <color rgba="0.8 0.8 0.8 1" />
    </material>
    <material name="dark_grey">
        <color rgba="0.2 0.2 0.2 1" />
    </material>
    <material name="light_blue">
        <color rgba="0.8 0.8 1 1" />
    </material>
    <material name="light_green">
        <color rgba="0.8 1 0.8 1" />
    </material>
    <material name="light_yellow">
        <color rgba="1 1 0.8 1" />
    </material>
    <!-- BAse link -->
    <link name="base_link">

    </link>
    <!-- chassis joint -->
    <joint name="chassis_joint" type="fixed">
        <parent link="base_link" />
        <child link="chassis" />
        <origin xyz="-.10 0 0" rpy="0 0 0" />
    </joint>
    <link name="chassis">

        <visual>
            <origin xyz="0.15 0 0.075" />
            <geometry>
                <box size=".3 .3 .15" />
            </geometry>
            <material name="light_grey" />
        </visual>
        <collision>


            <origin xyz="0.15 0 0.075" />
            <geometry>
                <box size=".3 .3 .15" />
            </geometry>


        </collision>
        <xacro:inertial_box mass="0.5" x=".3" y=".3" z=".15">
            <origin xyz="0.15 0 0.075" rpy="0 0 0" />
        </xacro:inertial_box>
    </link>
    <!-- Left Wheel Link -->
    <joint name="left_wheel_joint" type="continuous">
        <parent link="base_link" />
        <child link="left_wheel" />
        <origin xyz="0 0.175 0" rpy="-${pi/2} 0 0" />
        <axis xyz="0 0 1" />
    </joint>
    <link name="left_wheel">
        <visual>

            <geometry>
                <cylinder length="0.04" radius="0.05" />
            </geometry>
            <material name="black" />
        </visual>
        <collision>

            <geometry>
                <cylinder length="0.04" radius="0.05" />
            </geometry>

        </collision>
        <xacro:inertial_cylinder mass="0.1" length="0.04" radius="0.05">
            <origin xyz="0 0 0" rpy="0 0 0" />
        </xacro:inertial_cylinder>

    </link>
    <!-- Right Wheel Link -->
    <joint name="right_wheel_joint" type="continuous">
        <parent link="base_link" />
        <child link="right_wheel" />
        <origin xyz="0 -0.175 0" rpy="${pi/2} 0 0" />
        <axis xyz="0 0 -1" />
    </joint>
    <link name="right_wheel">
        <visual>
            <origin xyz="0 0 0" />
            <geometry>
                <cylinder length="0.04" radius="0.05" />
            </geometry>
            <material name="black" />
        </visual>
        <collision>

            <geometry>
                <cylinder length="0.04" radius="0.05" />
            </geometry>

        </collision>
        <xacro:inertial_cylinder mass="0.1" length="0.04" radius="0.05">
            <origin xyz="0 0 0" rpy="0 0 0" />
        </xacro:inertial_cylinder>

    </link>
    <!-- Caster Link -->
    <joint name="caster_wheel_joint" type="fixed">
        <parent link="chassis" />
        <child link="caster_wheel" />
        <origin xyz=".24 0 0" />
    </joint>
    <link name="caster_wheel">
        <visual>
            <origin xyz="0 0 0" />
            <geometry>
                <sphere radius="0.05" />
            </geometry>
            <material name="pink" />
        </visual>
        <collision>

            <geometry>
                <sphere radius="0.05" />
            </geometry>

        </collision>
        <xacro:inertial_sphere mass="0.1" radius="0.05">
            <origin xyz="0 0 0" rpy="0 0 0" />
        </xacro:inertial_sphere>
    </link>
</robot>